Workbook

Sheet Início
B1: CONTROLE DE FERRAMENTAS E PATRIMÔNIO
B3: EICES Engenharia — Instalações, Consultoria e Soluções Energéticas
B6: Manual de uso — leia antes de operar a planilha. Este arquivo é o padrão oficial da EICES para controle de ferramentas.
B8: 1. PARA QUE SERVE
B9: Registrar TODA ferramenta própria da EICES, saber onde cada uma está hoje, o que quebrou, o que está em manutenção,
B10: quanto se gasta de locação por mês e o que precisa comprar. Substitui os controles antigos — a partir de agora, tudo aqui.
B12: 2. AS 6 ABAS
B13: PATRIMÔNIO — cadastro de cada ferramenta própria (1 linha por ferramenta). É a base de tudo.
B14: MOVIMENTAÇÃO — o "filme": cada vez que uma ferramenta muda de obra, quebra, some ou é baixada, registre 1 linha aqui.
B15: MANUTENÇÃO — ficha de cada conserto: onde quebrou, custo, quando entrou e voltou.
B16: LOCADO — ferramentas alugadas de terceiros (Ônix, Impacto, etc.). Controla o custo mensal de locação. Ao devolver, preencha a Data Devolução.
B17: RÁDIO — controle à parte, por obra: quantidade, custo, quebra/sumiço, de quem foi descontado e devolução ao encerrar a obra.
... B34: 5. LEGENDA DE CORES
C35: Valor estimado (sem nota fiscal)
C36: Coluna automática — não editar (travada)
C37: Cabeçalho
B39: 6. PADRÃO DE CÓDIGO DE PATRIMÔNIO (proposta — PREFIXO-NN)
B40: Formato: 3 letras da categoria + hífen + número de 2 dígitos. Ex.: PAR-01 (parafusadeira 1), PEZ-02 (perfuratriz 2).
B41: Tabela de prefixos por categoria:
B42: PAR | C42: PARAFUSADEIRA | D42: FUR | E42: FURADEIRA | F42: ROM | G42: ROMPEDOR
B43: ESM | C43: ESMERILHADEIRA | D43: SMA | E43: SERRA MÁRMORE | F43: SES | G43: SERRA DE ESQUADRIA
B44: MT5 | C44: MARTELETE 5KG | D44: M10 | E44: MARTELETE 10KG | F44: LAS | G44: LASER
B45: TLA | C45: TRIPÉ LASER | D45: PEZ | E45: PERFURATRIZ | F45: PEX | G45: PERFURATRIZ EXTRATORA
B46: MOR | C46: MORSA | D46: TER | E46: TERMOFUSOR | F46: SOP | G46: SOPRADOR
B47: VAZ | C47: VAZADOR | D47: PFP | E47: PISTOLA FINCA PINO | F47: MTA | G47: MÁQUINA TESTE ÁGUA
B48: MTE | C48: MÁQUINA TESTE ELÉTRICA | D48: COM | E48: COMPRESSOR | F48: PPE | G48: PRENSA PEX
B49: PTE | C49: PRENSA TERMINAL | D49: PGA | E49: PRENSA GÁS | F49: MTI | G49: MÁQUINA DE TINTA
B50: MAN | C50: MANÔMETRO | D50: TCF | E50: TESOURA CORTA FERRO
B53: Código locado usa o código da própria locadora (quando vier na ferramenta). Rádio não usa código individual.

Sheet Patrimônio
B1: PATRIMÔNIO — FERRAMENTAS PRÓPRIAS EICES
B3: Cadastro-base. Preencha as colunas brancas. Cinza = automático.
A6: Código | B6: Categoria | C6: Item / Descrição | D6: Marca | E6: Modelo | F6: Nº de Série | G6: Valor (R$) | H6: Estimado? (S/N) | I6: Nota Fiscal | J6: Obra Atual | K6: Responsável | L6: Status | M6: Observação | N6: Locação EICES / mês (R$)
A7: PAR-01 | B7: PARAFUSADEIRA | C7: Parafusadeira | D7: BOSCH | E7: GSR 185 -LI | F7: 330 43 0275 | G7: 697.9 | H7: N | I7: 941194 | J7: {=IF($A7="","",IFERROR(_xlfn.XLOOKUP($A7,'Movimentação'!$B$7:$B$1006,'Movimentação'!$E$7:$E$1006,"",0,-1),""))} -> ESCRITÓRIO | K7: {=IF($A7="","",IFERROR(_xlfn.XLOOKUP($A7,'Movimentação'!$B$7:$B$1006,'Movimentação'!$G$7:$G$1006,"",0,-1),""))} -> LAÉRCIO | L7: =IF($A7="","",IF($Q7=1,"MANUTENÇÃO",IF($P7="BAIXA","BAIXADO",IF($P7="FURTO","FURTADO",IF($J7<>"","EM OBRA","PENDENTE-PROCURAR"))))) -> EM OBRA | N7: {=IF($A7="","",IFERROR(IF(OR($L7="BAIXADO",$L7="FURTADO"),0,INDEX(Listas!$J$2:$J$40,MATCH($B7,Listas!$I$2:$I$40,0))),""))} -> 200 | P7: {=IF($A7="","",IFERROR(_xlfn.XLOOKUP($A7,'Movimentação'!$B$7:$B$1006,'Movimentação'!$F$7:$F$1006,"",0,-1),""))} -> TRANSFERÊNCIA | Q7: =IF(COUNTIFS('Manutenção'!$B$7:$B$1006,$A7,'Manutenção'!$H$7:$H$1006,"EM CONSERTO")>0,1,0) -> 0
A8: PAR-02 | B8: PARAFUSADEIRA | C8: Parafusadeira | D8: BOSCH | E8: GSR 185 -LI | F8: 330 43 0280 | G8: 697.9 | H8: N | I8: 941194 | J8: {=IF($A8="","",IFERROR(_xlfn.XLOOKUP($A8,'Movimentação'!$B$7:$B$1006,'Movimentação'!$E$7:$E$1006,"",0,-1),""))} -> ARENGA (TRISUL) | K8: {=IF($A8="","",IFERROR(_xlfn.XLOOKUP($A8,'Movimentação'!$B$7:$B$1006,'Movimentação'!$G$7:$G$1006,"",0,-1),""))} -> LUCIENY | L8: =IF($A8="","",IF($Q8=1,"MANUTENÇÃO",IF($P8="BAIXA","BAIXADO",IF($P8="FURTO","FURTADO",IF($J8<>"","EM OBRA","PENDENTE-PROCURAR"))))) -> EM OBRA | N8: {=IF($A8="","",IFERROR(IF(OR($L8="BAIXADO",$L8="FURTADO"),0,INDEX(Listas!$J$2:$J$40,MATCH($B8,Listas!$I$2:$I$40,0))),""))} -> 200 | P8: {=IF($A8="","",IFERROR(_xlfn.XLOOKUP($A8,'Movimentação'!$B$7:$B$1006,'Movimentação'!$F$7:$F$1006,"",0,-1),""))} -> TRANSFERÊNCIA | Q8: =IF(COUNTIFS('Manutenção'!$B$7:$B$1006,$A8,'Manutenção'!$H$7:$H$1006,"EM CONSERTO")>0,1,0) -> 0
A9: PAR-03 | B9: PARAFUSADEIRA | C9: Parafusadeira | D9: BOSCH | E9: GSR 185 -LI | F9: 330 43 0274 | G9: 697.9 | H9: N | I9: 941194 | J9: {=IF($A9="","",IFERROR(_xlfn.XLOOKUP($A9,'Movimentação'!$B$7:$B$1006,'Movimentação'!$E$7:$E$1006,"",0,-1),""))} -> ALPHA ONE | K9: {=IF($A9="","",IFERROR(_xlfn.XLOOKUP($A9,'Movimentação'!$B$7:$B$1006,'Movimentação'!$G$7:$G$1006,"",0,-1),""))} -> EICES | L9: =IF($A9="","",IF($Q9=1,"MANUTENÇÃO",IF($P9="BAIXA","BAIXADO",IF($P9="FURTO","FURTADO",IF($J9<>"","EM OBRA","PENDENTE-PROCURAR"))))) -> FURTADO | N9: {=IF($A9="","",IFERROR(IF(OR($L9="BAIXADO",$L9="FURTADO"),0,INDEX(Listas!$J$2:$J$40,MATCH($B9,Listas!$I$2:$I$40,0))),""))} -> 0 | P9: {=IF($A9="","",IFERROR(_xlfn.XLOOKUP($A9,'Movimentação'!$B$7:$B$1006,'Movimentação'!$F$7:$F$1006,"",0,-1),""))} -> FURTO | Q9: =IF(COUNTIFS('Manutenção'!$B$7:$B$1006,$A9,'Manutenção'!$H$7:$H$1006,"EM CONSERTO")>0,1,0) -> 0
A10: PAR-04 | B10: PARAFUSADEIRA | C10: Parafusadeira | D10: BOSCH | E10: GSR 185 -LI | F10: 330 43 0279 | G10: 697.9 | H10: N | I10: 941194 | J10: {=IF($A10="","",IFERROR(_xlfn.XLOOKUP($A10,'Movimentação'!$B$7:$B$1006,'Movimentação'!$E$7:$E$1006,"",0,-1),""))} -> ALPHA ONE | K10: {=IF($A10="","",IFERROR(_xlfn.XLOOKUP($A10,'Movimentação'!$B$7:$B$1006,'Movimentação'!$G$7:$G$1006,"",0,-1),""))} -> EICES | L10: =IF($A10="","",IF($Q10=1,"MANUTENÇÃO",IF($P10="BAIXA","BAIXADO",IF($P10="FURTO","FURTADO",IF($J10<>"","EM OBRA","PENDENTE-PROCURAR"))))) -> BAIXADO | N10: {=IF($A10="","",IFERROR(IF(OR($L10="BAIXADO",$L10="FURTADO"),0,INDEX(Listas!$J$2:$J$40,MATCH($B10,Listas!$I$2:$I$40,0))),""))} -> 0 | P10: {=IF($A10="","",IFERROR(_xlfn.XLOOKUP($A10,'Movimentação'!$B$7:$B$1006,'Movimentação'!$F$7:$F$1006,"",0,-1),""))} -> BAIXA | Q10: =IF(COUNTIFS('Manutenção'!$B$7:$B$1006,$A10,'Manutenção'!$H$7:$H$1006,"EM CONSERTO")>0,1,0) -> 0
A11: PAR-05 | B11: PARAFUSADEIRA | C11: Parafusadeira | D11: BOSCH | E11: GSR 185 -LI | F11: 330 43 0273 | G11: 697.9 | H11: N | I11: 941194 | J11: {=IF($A11="","",IFERROR(_xlfn.XLOOKUP($A11,'Movimentação'!$B$7:$B$1006,'Movimentação'!$E$7:$E$1006,"",0,-1),""))} -> ASSISTENCIA TECNICA | K11: {=IF($A11="","",IFERROR(_xlfn.XLOOKUP($A11,'Movimentação'!$B$7:$B$1006,'Movimentação'!$G$7:$G$1006,"",0,-1),""))} -> EICES | L11: =IF($A11="","",IF($Q11=1,"MANUTENÇÃO",IF($P11="BAIXA","BAIXADO",IF($P11="FURTO","FURTADO",IF($J11<>"","EM OBRA","PENDENTE-PROCURAR"))))) -> BAIXADO | N11: {=IF($A11="","",IFERROR(IF(OR($L11="BAIXADO",$L11="FURTADO"),0,INDEX(Listas!$J$2:$J$40,MATCH($B11,Listas!$I$2:$I$40,0))),""))} -> 0 | P11: {=IF($A11="","",IFERROR(_xlfn.XLOOKUP($A11,'Movimentação'!$B$7:$B$1006,'Movimentação'!$F$7:$F$1006,"",0,-1),""))} -> BAIXA | Q11: =IF(COUNTIFS('Manutenção'!$B$7:$B$1006,$A11,'Manutenção'!$H$7:$H$1006,"EM CONSERTO")>0,1,0) -> 0
A12: PAR-5 | B12: PARAFUSADEIRA | C12: Parafusadeira | G12: 697.9 | H12: S | J12: {=IF($A12="","",IFERROR(_xlfn.XLOOKUP($A12,'Movimentação'!$B$7:$B$1006,'Movimentação'!$E$7:$E$1006,"",0,-1),""))} -> ASSISTENCIA TECNICA | K12: {=IF($A12="","",IFERROR(_xlfn.XLOOKUP($A12,'Movimentação'!$B$7:$B$1006,'Movimentação'!$G$7:$G$1006,"",0,-1),""))} -> EICES | L12: =IF($A12="","",IF($Q12=1,"MANUTENÇÃO",IF($P12="BAIXA","BAIXADO",IF($P12="FURTO","FURTADO",IF($J12<>"","EM OBRA","PENDENTE-PROCURAR"))))) -> BAIXADO | N12: {=IF($A12="","",IFERROR(IF(OR($L12="BAIXADO",$L12="FURTADO"),0,INDEX(Listas!$J$2:$J$40,MATCH($B12,Listas!$I$2:$I$40,0))),""))} -> 0 | P12: {=IF($A12="","",IFERROR(_xlfn.XLOOKUP($A12,'Movimentação'!$B$7:$B$1006,'Movimentação'!$F$7:$F$1006,"",0,-1),""))} -> BAIXA | Q12: =IF(COUNTIFS('Manutenção'!$B$7:$B$1006,$A12,'Manutenção'!$H$7:$H$1006,"EM CONSERTO")>0,1,0) -> 0
A13: PAR-06 | B13: PARAFUSADEIRA | C13: Parafusadeira | D13: BOSCH | E13: GSR 185 -LI | F13: 330 43 0281 | G13: 697.9 | H13: N | I13: 941194 | J13: {=IF($A13="","",IFERROR(_xlfn.XLOOKUP($A13,'Movimentação'!$B$7:$B$1006,'Movimentação'!$E$7:$E$1006,"",0,-1),""))} -> ASSISTENCIA TECNICA | K13: {=IF($A13="","",IFERROR(_xlfn.XLOOKUP($A13,'Movimentação'!$B$7:$B$1006,'Movimentação'!$G$7:$G$1006,"",0,-1),""))} -> EICES | L13: =IF($A13="","",IF($Q13=1,"MANUTENÇÃO",IF($P13="BAIXA","BAIXADO",IF($P13="FURTO","FURTADO",IF($J13<>"","EM OBRA","PENDENTE-PROCURAR"))))) -> BAIXADO | M13: em uso | N13: {=IF($A13="","",IFERROR(IF(OR($L13="BAIXADO",$L13="FURTADO"),0,INDEX(Listas!$J$2:$J$40,MATCH($B13,Listas!$I$2:$I$40,0))),""))} -> 0 | P13: {=IF($A13="","",IFERROR(_xlfn.XLOOKUP($A13,'Movimentação'!$B$7:$B$1006,'Movimentação'!$F$7:$F$1006,"",0,-1),""))} -> BAIXA | Q13: =IF(COUNTIFS('Manutenção'!$B$7:$B$1006,$A13,'Manutenção'!$H$7:$H$1006,"EM CONSERTO")>0,1,0) -> 0
A14: PAR-07 | B14: PARAFUSADEIRA | C14: Parafusadeira | D14: BOSCH | E14: 3601JF3EQ | F14: 3601JF3EQ (EICES-2) | G14: 697.9 | H14: S | I14: 1276 | J14: {=IF($A14="","",IFERROR(_xlfn.XLOOKUP($A14,'Movimentação'!$B$7:$B$1006,'Movimentação'!$E$7:$E$1006,"",0,-1),""))} -> TANABI | K14: {=IF($A14="","",IFERROR(_xlfn.XLOOKUP($A14,'Movimentação'!$B$7:$B$1006,'Movimentação'!$G$7:$G$1006,"",0,-1),""))} -> EICES | L14: =IF($A14="","",IF($Q14=1,"MANUTENÇÃO",IF($P14="BAIXA","BAIXADO",IF($P14="FURTO","FURTADO",IF($J14<>"","EM OBRA","PENDENTE-PROCURAR"))))) -> EM OBRA | N14: {=IF($A14="","",IFERROR(IF(OR($L14="BAIXADO",$L14="FURTADO"),0,INDEX(Listas!$J$2:$J$40,MATCH($B14,Listas!$I$2:$I$40,0))),""))} -> 200 | P14: {=IF($A14="","",IFERROR(_xlfn.XLOOKUP($A14,'Movimentação'!$B$7:$B$1006,'Movimentação'!$F$7:$F$1006,"",0,-1),""))} -> ENTRADA (NOVA) | Q14: =IF(COUNTIFS('Manutenção'!$B$7:$B$1006,$A14,'Manutenção'!$H$7:$H$1006,"EM CONSERTO")>0,1,0) -> 0
A15: PAR-08 | B15: PARAFUSADEIRA | C15: Parafusadeira | D15: BOSCH | E15: 3601JF3EQ | F15: 3601JF83E0 (EICES-1) | G15: 697.9 | H15: S | I15: 1276 | J15: {=IF($A15="","",IFERROR(_xlfn.XLOOKUP($A15,'Movimentação'!$B$7:$B$1006,'Movimentação'!$E$7:$E$1006,"",0,-1),""))} | K15: {=IF($A15="","",IFERROR(_xlfn.XLOOKUP($A15,'Movimentação'!$B$7:$B$1006,'Movimentação'!$G$7:$G$1006,"",0,-1),""))} | L15: =IF($A15="","",IF($Q15=1,"MANUTENÇÃO",IF($P15="BAIXA","BAIXADO",IF($P15="FURTO","FURTADO",IF($J15<>"","EM OBRA","PENDENTE-PROCURAR"))))) -> PENDENTE-PROCURAR | N15: {=IF($A15="","",IFERROR(IF(OR($L15="BAIXADO",$L15="FURTADO"),0,INDEX(Listas!$J$2:$J$40,MATCH($B15,Listas!$I$2:$I$40,0))),""))} -> 200 | P15: {=IF($A15="","",IFERROR(_xlfn.XLOOKUP($A15,'Movimentação'!$B$7:$B$1006,'Movimentação'!$F$7:$F$1006,"",0,-1),""))} | Q15: =IF(COUNTIFS('Manutenção'!$B$7:$B$1006,$A15,'Manutenção'!$H$7:$H$1006,"EM CONSERTO")>0,1,0) -> 0
A16: PAR-09 | B16: PARAFUSADEIRA | C16: Parafusadeira | D16: DEWALT | E16: DCD716 | F16: 2358 | G16: 779.01 | H16: N | I16: 1051559 | J16: {=IF($A16="","",IFERROR(_xlfn.XLOOKUP($A16,'Movimentação'!$B$7:$B$1006,'Movimentação'!$E$7:$E$1006,"",0,-1),""))} -> ASSISTENCIA TECNICA | K16: {=IF($A16="","",IFERROR(_xlfn.XLOOKUP($A16,'Movimentação'!$B$7:$B$1006,'Movimentação'!$G$7:$G$1006,"",0,-1),""))} -> EICES | L16: =IF($A16="","",IF($Q16=1,"MANUTENÇÃO",IF($P16="BAIXA","BAIXADO",IF($P16="FURTO","FURTADO",IF($J16<>"","EM OBRA","PENDENTE-PROCURAR"))))) -> BAIXADO | M16: sem carregador | N16: {=IF($A16="","",IFERROR(IF(OR($L16="BAIXADO",$L16="FURTADO"),0,INDEX(Listas!$J$2:$J$40,MATCH($B16,Listas!$I$2:$I$40,0))),""))} -> 0 | P16: {=IF($A16="","",IFERROR(_xlfn.XLOOKUP($A16,'Movimentação'!$B$7:$B$1006,'Movimentação'!$F$7:$F$1006,"",0,-1),""))} -> BAIXA | Q16: =IF(COUNTIFS('Manutenção'!$B$7:$B$1006,$A16,'Manutenção'!$H$7:$H$1006,"EM CONSERTO")>0,1,0) -> 0
A17: PAR-10 | B17: PARAFUSADEIRA | C17: Parafusadeira | D17: BOSCH | E17: GSB 180-LI | F17: 226200053 | G17: 806.67 | H17: N | J17: {=IF($A17="","",IFERROR(_xlfn.XLOOKUP($A17,'Movimentação'!$B$7:$B$1006,'Movimentação'!$E$7:$E$1006,"",0,-1),""))} | K17: {=IF($A17="","",IFERROR(_xlfn.XLOOKUP($A17,'Movimentação'!$B$7:$B$1006,'Movimentação'!$G$7:$G$1006,"",0,-1),""))} | L17: =IF($A17="","",IF($Q17=1,"MANUTENÇÃO",IF($P17="BAIXA","BAIXADO",IF($P17="FURTO","FURTADO",IF($J17<>"","EM OBRA","PENDENTE-PROCURAR"))))) -> PENDENTE-PROCURAR | N17: {=IF($A17="","",IFERROR(IF(OR($L17="BAIXADO",$L17="FURTADO"),0,INDEX(Listas!$J$2:$J$40,MATCH($B17,Listas!$I$2:$I$40,0))),""))} -> 200 | P17: {=IF($A17="","",IFERROR(_xlfn.XLOOKUP($A17,'Movimentação'!$B$7:$B$1006,'Movimentação'!$F$7:$F$1006,"",0,-1),""))} | Q17: =IF(COUNTIFS('Manutenção'!$B$7:$B$1006,$A17,'Manutenção'!$H$7:$H$1006,"EM CONSERTO")>0,1,0) -> 0
A18: PAR-11 | B18: PARAFUSADEIRA | C18: Parafusadeira | D18: NEWBEAT | E18: BRUSHLESS | F18: EW SI 0031 | G18: 697.9 | H18: S | J18: {=IF($A18="","",IFERROR(_xlfn.XLOOKUP($A18,'Movimentação'!$B$7:$B$1006,'Movimentação'!$E$7:$E$1006,"",0,-1),""))} -> MAURO | K18: {=IF($A18="","",IFERROR(_xlfn.XLOOKUP($A18,'Movimentação'!$B$7:$B$1006,'Movimentação'!$G$7:$G$1006,"",0,-1),""))} -> EICES | L18: =IF($A18="","",IF($Q18=1,"MANUTENÇÃO",IF($P18="BAIXA","BAIXADO",IF($P18="FURTO","FURTADO",IF($J18<>"","EM OBRA","PENDENTE-PROCURAR"))))) -> EM OBRA | N18: {=IF($A18="","",IFERROR(IF(OR($L18="BAIXADO",$L18="FURTADO"),0,INDEX(Listas!$J$2:$J$40,MATCH($B18,Listas!$I$2:$I$40,0))),""))} -> 200 | P18: {=IF($A18="","",IFERROR(_xlfn.XLOOKUP($A18,'Movimentação'!$B$7:$B$1006,'Movimentação'!$F$7:$F$1006,"",0,-1),""))} -> ENTRADA (NOVA) | Q18: =IF(COUNTIFS('Manutenção'!$B$7:$B$1006,$A18,'Manutenção'!$H$7:$H$1006,"EM CONSERTO")>0,1,0) -> 0
A19: PAR-12 | B19: PARAFUSADEIRA | C19: Parafusadeira | D19: NEWBEAT | E19: BRUSHLESS | F19: EW SI 0056 | G19: 697.9 | H19: S | J19: {=IF($A19="","",IFERROR(_xlfn.XLOOKUP($A19,'Movimentação'!$B$7:$B$1006,'Movimentação'!$E$7:$E$1006,"",0,-1),""))} -> ASSISTENCIA TECNICA | K19: {=IF($A19="","",IFERROR(_xlfn.XLOOKUP($A19,'Movimentação'!$B$7:$B$1006,'Movimentação'!$G$7:$G$1006,"",0,-1),""))} -> EICES | L19: =IF($A19="","",IF($Q19=1,"MANUTENÇÃO",IF($P19="BAIXA","BAIXADO",IF($P19="FURTO","FURTADO",IF($J19<>"","EM OBRA","PENDENTE-PROCURAR"))))) -> BAIXADO | N19: {=IF($A19="","",IFERROR(IF(OR($L19="BAIXADO",$L19="FURTADO"),0,INDEX(Listas!$J$2:$J$40,MATCH($B19,Listas!$I$2:$I$40,0))),""))} -> 0 | P19: {=IF($A19="","",IFERROR(_xlfn.XLOOKUP($A19,'Movimentação'!$B$7:$B$1006,'Movimentação'!$F$7:$F$1006,"",0,-1),""))} -> BAIXA | Q19: =IF(COUNTIFS('Manutenção'!$B$7:$B$1006,$A19,'Manutenção'!$H$7:$H$1006,"EM CONSERTO")>0,1,0) -> 0
A20: PAR-13 | B20: PARAFUSADEIRA | C20: Parafusadeira | D20: NEWBEAT | E20: BRUSHLESS | F20: EW SI 0057 | G20: 697.9 | H20: S | J20: {=IF($A20="","",IFERROR(_xlfn.XLOOKUP($A20,'Movimentação'!$B$7:$B$1006,'Movimentação'!$E$7:$E$1006,"",0,-1),""))} -> BALTAZAR | K20: {=IF($A20="","",IFERROR(_xlfn.XLOOKUP($A20,'Movimentação'!$B$7:$B$1006,'Movimentação'!$G$7:$G$1006,"",0,-1),""))} -> MARCIO | L20: =IF($A20="","",IF($Q20=1,"MANUTENÇÃO",IF($P20="BAIXA","BAIXADO",IF($P20="FURTO","FURTADO",IF($J20<>"","EM OBRA","PENDENTE-PROCURAR"))))) -> FURTADO | M20: em uso | N20: {=IF($A20="","",IFERROR(IF(OR($L20="BAIXADO",$L20="FURTADO"),0,INDEX(Listas!$J$2:$J$40,MATCH($B20,Listas!$I$2:$I$40,0))),""))} -> 0 | P20: {=IF($A20="","",IFERROR(_xlfn.XLOOKUP($A20,'Movimentação'!$B$7:$B$1006,'Movimentação'!$F$7:$F$1006,"",0,-1),""))} -> FURTO | Q20: =IF(COUNTIFS('Manutenção'!$B$7:$B$1006,$A20,'Manutenção'!$H$7:$H$1006,"EM CONSERTO")>0,1,0) -> 0
A21: PAR-14 | B21: PARAFUSADEIRA | C21: Parafusadeira | D21: NEWBEAT | E21: BRUSHLESS | F21: EW SI 0035 | G21: 697.9 | H21: S | J21: {=IF($A21="","",IFERROR(_xlfn.XLOOKUP($A21,'Movimentação'!$B$7:$B$1006,'Movimentação'!$E$7:$E$1006,"",0,-1),""))} -> JOA | K21: {=IF($A21="","",IFERROR(_xlfn.XLOOKUP($A21,'Movimentação'!$B$7:$B$1006,'Movimentação'!$G$7:$G$1006,"",0,-1),""))} -> GABRIEL | L21: =IF($A21="","",IF($Q21=1,"MANUTENÇÃO",IF($P21="BAIXA","BAIXADO",IF($P21="FURTO","FURTADO",IF($J21<>"","EM OBRA","PENDENTE-PROCURAR"))))) -> EM OBRA | N21: {=IF($A21="","",IFERROR(IF(OR($L21="BAIXADO",$L21="FURTADO"),0,INDEX(Listas!$J$2:$J$40,MATCH($B21,Listas!$I$2:$I$40,0))),""))} -> 200 | P21: {=IF($A21="","",IFERROR(_xlfn.XLOOKUP($A21,'Movimentação'!$B$7:$B$1006,'Movimentação'!$F$7:$F$1006,"",0,-1),""))} -> TRANSFERÊNCIA | Q21: =IF(COUNTIFS('Manutenção'!$B$7:$B$1006,$A21,'Manutenção'!$H$7:$H$1006,"EM CONSERTO")>0,1,0) -> 0
A22: PAR-15 | B22: PARAFUSADEIRA | C22: Parafusadeira | D22: NEWBEAT | E22: BRUSHLESS | F22: EW SI 0023 | G22: 697.9 | H22: S | J22: {=IF($A22="","",IFERROR(_xlfn.XLOOKUP($A22,'Movimentação'!$B$7:$B$1006,'Movimentação'!$E$7:$E$1006,"",0,-1),""))} -> ASSISTENCIA TECNICA | K22: {=IF($A22="","",IFERROR(_xlfn.XLOOKUP($A22,'Movimentação'!$B$7:$B$1006,'Movimentação'!$G$7:$G$1006,"",0,-1),""))} -> EICES | L22: =IF($A22="","",IF($Q22=1,"MANUTENÇÃO",IF($P22="BAIXA","BAIXADO",IF($P22="FURTO","FURTADO",IF($J22<>"","EM OBRA","PENDENTE-PROCURAR"))))) -> BAIXADO | N22: {=IF($A22="","",IFERROR(IF(OR($L22="BAIXADO",$L22="FURTADO"),0,INDEX(Listas!$J$2:$J$40,MATCH($B22,Listas!$I$2:$I$40,0))),""))} -> 0 | P22: {=IF($A22="","",IFERROR(_xlfn.XLOOKUP($A22,'Movimentação'!$B$7:$B$1006,'Movimentação'!$F$7:$F$1006,"",0,-1),""))} -> BAIXA | Q22: =IF(COUNTIFS('Manutenção'!$B$7:$B$1006,$A22,'Manutenção'!$H$7:$H$1006,"EM CONSERTO")>0,1,0) -> 0
A23: PAR-16 | B23: PARAFUSADEIRA | C23: Parafusadeira | D23: NEWBEAT | E23: BRUSHLESS | G23: 697.9 | H23: S | J23: {=IF($A23="","",IFERROR(_xlfn.XLOOKUP($A23,'Movimentação'!$B$7:$B$1006,'Movimentação'!$E$7:$E$1006,"",0,-1),""))} | K23: {=IF($A23="","",IFERROR(_xlfn.XLOOKUP($A23,'Movimentação'!$B$7:$B$1006,'Movimentação'!$G$7:$G$1006,"",0,-1),""))} | L23: =IF($A23="","",IF($Q23=1,"MANUTENÇÃO",IF($P23="BAIXA","BAIXADO",IF($P23="FURTO","FURTADO",IF($J23<>"","EM OBRA","PENDENTE-PROCURAR"))))) -> PENDENTE-PROCURAR | N23: {=IF($A23="","",IFERROR(IF(OR($L23="BAIXADO",$L23="FURTADO"),0,INDEX(Listas!$J$2:$J$40,MATCH($B23,Listas!$I$2:$I$40,0))),""))} -> 200 | P23: {=IF($A23="","",IFERROR(_xlfn.XLOOKUP($A23,'Movimentação'!$B$7:$B$1006,'Movimentação'!$F$7:$F$1006,"",0,-1),""))} | Q23: =IF(COUNTIFS('Manutenção'!$B$7:$B$1006,$A23,'Manutenção'!$H$7:$H$1006,"EM CONSERTO")>0,1,0) -> 0
A24: PAR-17 | B24: PARAFUSADEIRA | C24: Parafusadeira | D24: ARITA | E24: AR-M1370PRO | F24: DR130A01667 | G24: 697.9 | H24: S | J24: {=IF($A24="","",IFERROR(_xlfn.XLOOKUP($A24,'Movimentação'!$B$7:$B$1006,'Movimentação'!$E$7:$E$1006,"",0,-1),""))} -> PJM | K24: {=IF($A24="","",IFERROR(_xlfn.XLOOKUP($A24,'Movimentação'!$B$7:$B$1006,'Movimentação'!$G$7:$G$1006,"",0,-1),""))} -> EICES | L24: =IF($A24="","",IF($Q24=1,"MANUTENÇÃO",IF($P24="BAIXA","BAIXADO",IF($P24="FURTO","FURTADO",IF($J24<>"","EM OBRA","PENDENTE-PROCURAR"))))) -> EM OBRA | N24: {=IF($A24="","",IFERROR(IF(OR($L24="BAIXADO",$L24="FURTADO"),0,INDEX(Listas!$J$2:$J$40,MATCH($B24,Listas!$I$2:$I$40,0))),""))} -> 200 | P24: {=IF($A24="","",IFERROR(_xlfn.XLOOKUP($A24,'Movimentação'!$B$7:$B$1006,'Movimentação'!$F$7:$F$1006,"",0,-1),""))} -> ENTRADA (NOVA) | Q24: =IF(COUNTIFS('Manutenção'!$B$7:$B$1006,$A24,'Manutenção'!$H$7:$H$1006,"EM CONSERTO")>0,1,0) -> 0
A25: PAR-18 | B25: PARAFUSADEIRA | C25: Parafusadeira | D25: ARITA | E25: AR-M1370PRO | F25: DR13A001666 | G25: 697.9 | H25: S | J25: {=IF($A25="","",IFERROR(_xlfn.XLOOKUP($A25,'Movimentação'!$B$7:$B$1006,'Movimentação'!$E$7:$E$1006,"",0,-1),""))} -> ANGELICA | K25: THIAGO | L25: =IF($A25="","",IF($Q25=1,"MANUTENÇÃO",IF($P25="BAIXA","BAIXADO",IF($P25="FURTO","FURTADO",IF($J25<>"","EM OBRA","PENDENTE-PROCURAR"))))) -> EM OBRA | N25: {=IF($A25="","",IFERROR(IF(OR($L25="BAIXADO",$L25="FURTADO"),0,INDEX(Listas!$J$2:$J$40,MATCH($B25,Listas!$I$2:$I$40,0))),""))} -> 200 | P25: {=IF($A25="","",IFERROR(_xlfn.XLOOKUP($A25,'Movimentação'!$B$7:$B$1006,'Movimentação'!$F$7:$F$1006,"",0,-1),""))} -> RETORNO MANUTENÇÃO | Q25: =IF(COUNTIFS('Manutenção'!$B$7:$B$1006,$A25,'Manutenção'!$H$7:$H$1006,"EM CONSERTO")>0,1,0) -> 0
A26: PAR-19 | B26: PARAFUSADEIRA | C26: Parafusadeira | D26: ARITA | E26: AR-M1370PRO | F26: DR13A001599 | G26: 697.9 | H26: S | J26: {=IF($A26="","",IFERROR(_xlfn.XLOOKUP($A26,'Movimentação'!$B$7:$B$1006,'Movimentação'!$E$7:$E$1006,"",0,-1),""))} -> ORIÇANGA | K26: {=IF($A26="","",IFERROR(_xlfn.XLOOKUP($A26,'Movimentação'!$B$7:$B$1006,'Movimentação'!$G$7:$G$1006,"",0,-1),""))} -> EICES | L26: =IF($A26="","",IF($Q26=1,"MANUTENÇÃO",IF($P26="BAIXA","BAIXADO",IF($P26="FURTO","FURTADO",IF($J26<>"","EM OBRA","PENDENTE-PROCURAR"))))) -> EM OBRA | N26: {=IF($A26="","",IFERROR(IF(OR($L26="BAIXADO",$L26="FURTADO"),0,INDEX(Listas!$J$2:$J$40,MATCH($B26,Listas!$I$2:$I$40,0))),""))} -> 200 | P26: {=IF($A26="","",IFERROR(_xlfn.XLOOKUP($A26,'Movimentação'!$B$7:$B$1006,'Movimentação'!$F$7:$F$1006,"",0,-1),""))} -> ENTRADA (NOVA) | Q26: =IF(COUNTIFS('Manutenção'!$B$7:$B$1006,$A26,'Manutenção'!$H$7:$H$1006,"EM CONSERTO")>0,1,0) -> 0
A27: PAR-20 | B27: PARAFUSADEIRA | C27: Parafusadeira | D27: ARITA | E27: AR-M1370PRO | F27: DR13A001600 | G27: 697.9 | H27: S | J27: {=IF($A27="","",IFERROR(_xlfn.XLOOKUP($A27,'Movimentação'!$B$7:$B$1006,'Movimentação'!$E$7:$E$1006,"",0,-1),""))} -> SAMPA CONSOLAÇÃO | K27: {=IF($A27="","",IFERROR(_xlfn.XLOOKUP($A27,'Movimentação'!$B$7:$B$1006,'Movimentação'!$G$7:$G$1006,"",0,-1),""))} -> EICES | L27: =IF($A27="","",IF($Q27=1,"MANUTENÇÃO",IF($P27="BAIXA","BAIXADO",IF($P27="FURTO","FURTADO",IF($J27<>"","EM OBRA","PENDENTE-PROCURAR"))))) -> EM OBRA | N27: {=IF($A27="","",IFERROR(IF(OR($L27="BAIXADO",$L27="FURTADO"),0,INDEX(Listas!$J$2:$J$40,MATCH($B27,Listas!$I$2:$I$40,0))),""))} -> 200 | P27: {=IF($A27="","",IFERROR(_xlfn.XLOOKUP($A27,'Movimentação'!$B$7:$B$1006,'Movimentação'!$F$7:$F$1006,"",0,-1),""))} -> ENTRADA (NOVA) | Q27: =IF(COUNTIFS('Manutenção'!$B$7:$B$1006,$A27,'Manutenção'!$H$7:$H$1006,"EM CONSERTO")>0,1,0) -> 0
A28: PAR-21 | B28: PARAFUSADEIRA | C28: Parafusadeira | D28: ARITA | E28: AR-M1370PRO | F28: DR13A001823 | G28: 697.9 | H28: S | J28: {=IF($A28="","",IFERROR(_xlfn.XLOOKUP($A28,'Movimentação'!$B$7:$B$1006,'Movimentação'!$E$7:$E$1006,"",0,-1),""))} -> PJM | K28: {=IF($A28="","",IFERROR(_xlfn.XLOOKUP($A28,'Movimentação'!$B$7:$B$1006,'Movimentação'!$G$7:$G$1006,"",0,-1),""))} -> EICES | L28: =IF($A28="","",IF($Q28=1,"MANUTENÇÃO",IF($P28="BAIXA","BAIXADO",IF($P28="FURTO","FURTADO",IF($J28<>"","EM OBRA","PENDENTE-PROCURAR"))))) -> EM OBRA | N28: {=IF($A28="","",IFERROR(IF(OR($L28="BAIXADO",$L28="FURTADO"),0,INDEX(Listas!$J$2:$J$40,MATCH($B28,Listas!$I$2:$I$40,0))),""))} -> 200 | P28: {=IF($A28="","",IFERROR(_xlfn.XLOOKUP($A28,'Movimentação'!$B$7:$B$1006,'Movimentação'!$F$7:$F$1006,"",0,-1),""))} -> ENTRADA (NOVA) | Q28: =IF(COUNTIFS('Manutenção'!$B$7:$B$1006,$A28,'Manutenção'!$H$7:$H$1006,"EM CONSERTO")>0,1,0) -> 0
A29: FRP-01 | B29: ROMPEDOR | C29: Rompedor | D29: BOSCH | E29: GBH 2-28 D | F29: 329 000 519 | G29: 1162.19 | H29: N | I29: 952463 | J29: {=IF($A29="","",IFERROR(_xlfn.XLOOKUP($A29,'Movimentação'!$B$7:$B$1006,'Movimentação'!$E$7:$E$1006,"",0,-1),""))} -> ORIÇANGA | K29: {=IF($A29="","",IFERROR(_xlfn.XLOOKUP($A29,'Movimentação'!$B$7:$B$1006,'Movimentação'!$G$7:$G$1006,"",0,-1),""))} -> EICES | L29: =IF($A29="","",IF($Q29=1,"MANUTENÇÃO",IF($P29="BAIXA","BAIXADO",IF($P29="FURTO","FURTADO",IF($J29<>"","EM OBRA","PENDENTE-PROCURAR"))))) -> EM OBRA | M29: OBS NÃO ENCONTRADO 31/08 | N29: {=IF($A29="","",IFERROR(IF(OR($L29="BAIXADO",$L29="FURTADO"),0,INDEX(Listas!$J$2:$J$40,MATCH($B29,Listas!$I$2:$I$40,0))),""))} -> 200 | P29: {=IF($A29="","",IFERROR(_xlfn.XLOOKUP($A29,'Movimentação'!$B$7:$B$1006,'Movimentação'!$F$7:$F$1006,"",0,-1),""))} -> ENTRADA (NOVA) | Q29: =IF(COUNTIFS('Manutenção'!$B$7:$B$1006,$A29,'Manutenção'!$H$7:$H$1006,"EM CONSERTO")>0,1,0) -> 0
A30: FRP-02 | B30: ROMPEDOR | C30: Rompedor | D30: BOSCH | E30: GBH 2-28 D | F30: 3911BAU2E0 | G30: 903.9 | H30: N | I30: 1051559 | J30: ASSISTENCIA TECNICA | K30: {=IF($A30="","",IFERROR(_xlfn.XLOOKUP($A30,'Movimentação'!$B$7:$B$1006,'Movimentação'!$G$7:$G$1006,"",0,-1),""))} -> EICES | L30: =IF($A30="","",IF($Q30=1,"MANUTENÇÃO",IF($P30="BAIXA","BAIXADO",IF($P30="FURTO","FURTADO",IF($J30<>"","EM OBRA","PENDENTE-PROCURAR"))))) -> BAIXADO | N30: {=IF($A30="","",IFERROR(IF(OR($L30="BAIXADO",$L30="FURTADO"),0,INDEX(Listas!$J$2:$J$40,MATCH($B30,Listas!$I$2:$I$40,0))),""))} -> 0 | P30: {=IF($A30="","",IFERROR(_xlfn.XLOOKUP($A30,'Movimentação'!$B$7:$B$1006,'Movimentação'!$F$7:$F$1006,"",0,-1),""))} -> BAIXA | Q30: =IF(COUNTIFS('Manutenção'!$B$7:$B$1006,$A30,'Manutenção'!$H$7:$H$1006,"EM CONSERTO")>0,1,0) -> 0
A31: FRP-03 | B31: ROMPEDOR | C31: Rompedor | D31: BOSCH | E31: GBH 2-28 D | F31: 3611BA02E0 | G31: 903.9 | H31: N | I31: 1051559 | J31: {=IF($A31="","",IFERROR(_xlfn.XLOOKUP($A31,'Movimentação'!$B$7:$B$1006,'Movimentação'!$E$7:$E$1006,"",0,-1),""))} -> ASSISTENCIA TECNICA | K31: {=IF($A31="","",IFERROR(_xlfn.XLOOKUP($A31,'Movimentação'!$B$7:$B$1006,'Movimentação'!$G$7:$G$1006,"",0,-1),""))} -> EICES | L31: =IF($A31="","",IF($Q31=1,"MANUTENÇÃO",IF($P31="BAIXA","BAIXADO",IF($P31="FURTO","FURTADO",IF($J31<>"","EM OBRA","PENDENTE-PROCURAR"))))) -> BAIXADO | N31: {=IF($A31="","",IFERROR(IF(OR($L31="BAIXADO",$L31="FURTADO"),0,INDEX(Listas!$J$2:$J$40,MATCH($B31,Listas!$I$2:$I$40,0))),""))} -> 0 | P31: {=IF($A31="","",IFERROR(_xlfn.XLOOKUP($A31,'Movimentação'!$B$7:$B$1006,'Movimentação'!$F$7:$F$1006,"",0,-1),""))} -> BAIXA | Q31: =IF(COUNTIFS('Manutenção'!$B$7:$B$1006,$A31,'Manutenção'!$H$7:$H$1006,"EM CONSERTO")>0,1,0) -> 0
A32: FRP-04 | B32: ROMPEDOR | C32: Rompedor | F32: 609361800 | G32: 903.9 | H32: S | J32: {=IF($A32="","",IFERROR(_xlfn.XLOOKUP($A32,'Movimentação'!$B$7:$B$1006,'Movimentação'!$E$7:$E$1006,"",0,-1),""))} | K32: {=IF($A32="","",IFERROR(_xlfn.XLOOKUP($A32,'Movimentação'!$B$7:$B$1006,'Movimentação'!$G$7:$G$1006,"",0,-1),""))} | L32: =IF($A32="","",IF($Q32=1,"MANUTENÇÃO",IF($P32="BAIXA","BAIXADO",IF($P32="FURTO","FURTADO",IF($J32<>"","EM OBRA","PENDENTE-PROCURAR"))))) -> PENDENTE-PROCURAR | N32: {=IF($A32="","",IFERROR(IF(OR($L32="BAIXADO",$L32="FURTADO"),0,INDEX(Listas!$J$2:$J$40,MATCH($B32,Listas!$I$2:$I$40,0))),""))} -> 200 | P32: {=IF($A32="","",IFERROR(_xlfn.XLOOKUP($A32,'Movimentação'!$B$7:$B$1006,'Movimentação'!$F$7:$F$1006,"",0,-1),""))} | Q32: =IF(COUNTIFS('Manutenção'!$B$7:$B$1006,$A32,'Manutenção'!$H$7:$H$1006,"EM CONSERTO")>0,1,0) -> 0
A33: FRP-05 | B33: ROMPEDOR | C33: Rompedor | D33: THAF | E33: H26F-3 | F33: 202400041 | G33: 903.9 | H33: S | J33: {=IF($A33="","",IFERROR(_xlfn.XLOOKUP($A33,'Movimentação'!$B$7:$B$1006,'Movimentação'!$E$7:$E$1006,"",0,-1),""))} -> TANABI | K33: {=IF($A33="","",IFERROR(_xlfn.XLOOKUP($A33,'Movimentação'!$B$7:$B$1006,'Movimentação'!$G$7:$G$1006,"",0,-1),""))} -> EICES | L33: =IF($A33="","",IF($Q33=1,"MANUTENÇÃO",IF($P33="BAIXA","BAIXADO",IF($P33="FURTO","FURTADO",IF($J33<>"","EM OBRA","PENDENTE-PROCURAR"))))) -> EM OBRA | N33: {=IF($A33="","",IFERROR(IF(OR($L33="BAIXADO",$L33="FURTADO"),0,INDEX(Listas!$J$2:$J$40,MATCH($B33,Listas!$I$2:$I$40,0))),""))} -> 200 | P33: {=IF($A33="","",IFERROR(_xlfn.XLOOKUP($A33,'Movimentação'!$B$7:$B$1006,'Movimentação'!$F$7:$F$1006,"",0,-1),""))} -> ENTRADA (NOVA) | Q33: =IF(COUNTIFS('Manutenção'!$B$7:$B$1006,$A33,'Manutenção'!$H$7:$H$1006,"EM CONSERTO")>0,1,0) -> 0
A34: FRP-06 | B34: ROMPEDOR | C34: Rompedor | D34: THAF | E34: H26F-3 | F34: 202400138 | G34: 903.9 | H34: S | J34: {=IF($A34="","",IFERROR(_xlfn.XLOOKUP($A34,'Movimentação'!$B$7:$B$1006,'Movimentação'!$E$7:$E$1006,"",0,-1),""))} -> SAMPA CONSOLAÇÃO | K34: {=IF($A34="","",IFERROR(_xlfn.XLOOKUP($A34,'Movimentação'!$B$7:$B$1006,'Movimentação'!$G$7:$G$1006,"",0,-1),""))} -> TIAGO | L34: =IF($A34="","",IF($Q34=1,"MANUTENÇÃO",IF($P34="BAIXA","BAIXADO",IF($P34="FURTO","FURTADO",IF($J34<>"","EM OBRA","PENDENTE-PROCURAR"))))) -> EM OBRA | N34: {=IF($A34="","",IFERROR(IF(OR($L34="BAIXADO",$L34="FURTADO"),0,INDEX(Listas!$J$2:$J$40,MATCH($B34,Listas!$I$2:$I$40,0))),""))} -> 200 | P34: {=IF($A34="","",IFERROR(_xlfn.XLOOKUP($A34,'Movimentação'!$B$7:$B$1006,'Movimentação'!$F$7:$F$1006,"",0,-1),""))} -> RETORNO MANUTENÇÃO | Q34: =IF(COUNTIFS('Manutenção'!$B$7:$B$1006,$A34,'Manutenção'!$H$7:$H$1006,"EM CONSERTO")>0,1,0) -> 0
A35: FRP-07 | B35: ROMPEDOR | C35: Rompedor | D35: THAF | E35: H26F-3 | F35: 202400850 | G35: 903.9 | H35: S | J35: {=IF($A35="","",IFERROR(_xlfn.XLOOKUP($A35,'Movimentação'!$B$7:$B$1006,'Movimentação'!$E$7:$E$1006,"",0,-1),""))} -> ALPHA ONE | K35: {=IF($A35="","",IFERROR(_xlfn.XLOOKUP($A35,'Movimentação'!$B$7:$B$1006,'Movimentação'!$G$7:$G$1006,"",0,-1),""))} -> EICES | L35: =IF($A35="","",IF($Q35=1,"MANUTENÇÃO",IF($P35="BAIXA","BAIXADO",IF($P35="FURTO","FURTADO",IF($J35<>"","EM OBRA","PENDENTE-PROCURAR"))))) -> BAIXADO | N35: {=IF($A35="","",IFERROR(IF(OR($L35="BAIXADO",$L35="FURTADO"),0,INDEX(Listas!$J$2:$J$40,MATCH($B35,Listas!$I$2:$I$40,0))),""))} -> 0 | P35: {=IF($A35="","",IFERROR(_xlfn.XLOOKUP($A35,'Movimentação'!$B$7:$B$1006,'Movimentação'!$F$7:$F$1006,"",0,-1),""))} -> BAIXA | Q35: =IF(COUNTIFS('Manutenção'!$B$7:$B$1006,$A35,'Manutenção'!$H$7:$H$1006,"EM CONSERTO")>0,1,0) -> 0
A36: FRP-08 | B36: ROMPEDOR | C36: Rompedor | D36: THAF | E36: H26F-3 | G36: 903.9 | H36: S | J36: {=IF($A36="","",IFERROR(_xlfn.XLOOKUP($A36,'Movimentação'!$B$7:$B$1006,'Movimentação'!$E$7:$E$1006,"",0,-1),""))} -> MAURO | K36: {=IF($A36="","",IFERROR(_xlfn.XLOOKUP($A36,'Movimentação'!$B$7:$B$1006,'Movimentação'!$G$7:$G$1006,"",0,-1),""))} -> EICES | L36: =IF($A36="","",IF($Q36=1,"MANUTENÇÃO",IF($P36="BAIXA","BAIXADO",IF($P36="FURTO","FURTADO",IF($J36<>"","EM OBRA","PENDENTE-PROCURAR"))))) -> EM OBRA | N36: {=IF($A36="","",IFERROR(IF(OR($L36="BAIXADO",$L36="FURTADO"),0,INDEX(Listas!$J$2:$J$40,MATCH($B36,Listas!$I$2:$I$40,0))),""))} -> 200 | P36: {=IF($A36="","",IFERROR(_xlfn.XLOOKUP($A36,'Movimentação'!$B$7:$B$1006,'Movimentação'!$F$7:$F$1006,"",0,-1),""))} -> ENTRADA (NOVA) | Q36: =IF(COUNTIFS('Manutenção'!$B$7:$B$1006,$A36,'Manutenção'!$H$7:$H$1006,"EM CONSERTO")>0,1,0) -> 0
A37: FRP-09 | B37: ROMPEDOR | C37: Rompedor | D37: THAF | E37: H26F-3 | F37: 202401394 | G37: 903.9 | H37: S | J37: {=IF($A37="","",IFERROR(_xlfn.XLOOKUP($A37,'Movimentação'!$B$7:$B$1006,'Movimentação'!$E$7:$E$1006,"",0,-1),""))} -> MANUTENÇÃO | K37: {=IF($A37="","",IFERROR(_xlfn.XLOOKUP($A37,'Movimentação'!$B$7:$B$1006,'Movimentação'!$G$7:$G$1006,"",0,-1),""))} -> LAÉRCIO | L37: =IF($A37="","",IF($Q37=1,"MANUTENÇÃO",IF($P37="BAIXA","BAIXADO",IF($P37="FURTO","FURTADO",IF($J37<>"","EM OBRA","PENDENTE-PROCURAR"))))) -> EM OBRA | N37: {=IF($A37="","",IFERROR(IF(OR($L37="BAIXADO",$L37="FURTADO"),0,INDEX(Listas!$J$2:$J$40,MATCH($B37,Listas!$I$2:$I$40,0))),""))} -> 200 | P37: {=IF($A37="","",IFERROR(_xlfn.XLOOKUP($A37,'Movimentação'!$B$7:$B$1006,'Movimentação'!$F$7:$F$1006,"",0,-1),""))} -> ENVIO P/ MANUTENÇÃO | Q37: =IF(COUNTIFS('Manutenção'!$B$7:$B$1006,$A37,'Manutenção'!$H$7:$H$1006,"EM CONSERTO")>0,1,0) -> 0
A38: FRP-10 | B38: ROMPEDOR | C38: Rompedor | D38: THAF | E38: H26F-3 | F38: 202402289 | G38: 903.9 | H38: S | J38: {=IF($A38="","",IFERROR(_xlfn.XLOOKUP($A38,'Movimentação'!$B$7:$B$1006,'Movimentação'!$E$7:$E$1006,"",0,-1),""))} -> JOA | K38: {=IF($A38="","",IFERROR(_xlfn.XLOOKUP($A38,'Movimentação'!$B$7:$B$1006,'Movimentação'!$G$7:$G$1006,"",0,-1),""))} -> EICES | L38: =IF($A38="","",IF($Q38=1,"MANUTENÇÃO",IF($P38="BAIXA","BAIXADO",IF($P38="FURTO","FURTADO",IF($J38<>"","EM OBRA","PENDENTE-PROCURAR"))))) -> EM OBRA | N38: {=IF($A38="","",IFERROR(IF(OR($L38="BAIXADO",$L38="FURTADO"),0,INDEX(Listas!$J$2:$J$40,MATCH($B38,Listas!$I$2:$I$40,0))),""))} -> 200 | P38: {=IF($A38="","",IFERROR(_xlfn.XLOOKUP($A38,'Movimentação'!$B$7:$B$1006,'Movimentação'!$F$7:$F$1006,"",0,-1),""))} -> ENTRADA (NOVA) | Q38: =IF(COUNTIFS('Manutenção'!$B$7:$B$1006,$A38,'Manutenção'!$H$7:$H$1006,"EM CONSERTO")>0,1,0) -> 0
A39: FRP-11 | B39: ROMPEDOR | C39: Rompedor | D39: THAF | E39: H26F-3 | F39: 202402281 | G39: 903.9 | H39: S | J39: {=IF($A39="","",IFERROR(_xlfn.XLOOKUP($A39,'Movimentação'!$B$7:$B$1006,'Movimentação'!$E$7:$E$1006,"",0,-1),""))} -> PJM | K39: {=IF($A39="","",IFERROR(_xlfn.XLOOKUP($A39,'Movimentação'!$B$7:$B$1006,'Movimentação'!$G$7:$G$1006,"",0,-1),""))} -> EICES | L39: =IF($A39="","",IF($Q39=1,"MANUTENÇÃO",IF($P39="BAIXA","BAIXADO",IF($P39="FURTO","FURTADO",IF($J39<>"","EM OBRA","PENDENTE-PROCURAR"))))) -> EM OBRA | N39: {=IF($A39="","",IFERROR(IF(OR($L39="BAIXADO",$L39="FURTADO"),0,INDEX(Listas!$J$2:$J$40,MATCH($B39,Listas!$I$2:$I$40,0))),""))} -> 200 | P39: {=IF($A39="","",IFERROR(_xlfn.XLOOKUP($A39,'Movimentação'!$B$7:$B$1006,'Movimentação'!$F$7:$F$1006,"",0,-1),""))} -> ENTRADA (NOVA) | Q39: =IF(COUNTIFS('Manutenção'!$B$7:$B$1006,$A39,'Manutenção'!$H$7:$H$1006,"EM CONSERTO")>0,1,0) -> 0
A40: FRP-12 | B40: ROMPEDOR | C40: Rompedor | D40: THAF | E40: H26F-3 | F40: 202402285 | G40: 903.9 | H40: S | J40: {=IF($A40="","",IFERROR(_xlfn.XLOOKUP($A40,'Movimentação'!$B$7:$B$1006,'Movimentação'!$E$7:$E$1006,"",0,-1),""))} -> SAMPA CONSOLAÇÃO | K40: {=IF($A40="","",IFERROR(_xlfn.XLOOKUP($A40,'Movimentação'!$B$7:$B$1006,'Movimentação'!$G$7:$G$1006,"",0,-1),""))} -> EICES | L40: =IF($A40="","",IF($Q40=1,"MANUTENÇÃO",IF($P40="BAIXA","BAIXADO",IF($P40="FURTO","FURTADO",IF($J40<>"","EM OBRA","PENDENTE-PROCURAR"))))) -> EM OBRA | N40: {=IF($A40="","",IFERROR(IF(OR($L40="BAIXADO",$L40="FURTADO"),0,INDEX(Listas!$J$2:$J$40,MATCH($B40,Listas!$I$2:$I$40,0))),""))} -> 200 | P40: {=IF($A40="","",IFERROR(_xlfn.XLOOKUP($A40,'Movimentação'!$B$7:$B$1006,'Movimentação'!$F$7:$F$1006,"",0,-1),""))} -> ENTRADA (NOVA) | Q40: =IF(COUNTIFS('Manutenção'!$B$7:$B$1006,$A40,'Manutenção'!$H$7:$H$1006,"EM CONSERTO")>0,1,0) -> 0
A41: FRP-13 | B41: ROMPEDOR | C41: Rompedor | D41: THAF | E41: H26F-3 | F41: 202402283 | G41: 903.9 | H41: S | J41: {=IF($A41="","",IFERROR(_xlfn.XLOOKUP($A41,'Movimentação'!$B$7:$B$1006,'Movimentação'!$E$7:$E$1006,"",0,-1),""))} | K41: {=IF($A41="","",IFERROR(_xlfn.XLOOKUP($A41,'Movimentação'!$B$7:$B$1006,'Movimentação'!$G$7:$G$1006,"",0,-1),""))} | L41: =IF($A41="","",IF($Q41=1,"MANUTENÇÃO",IF($P41="BAIXA","BAIXADO",IF($P41="FURTO","FURTADO",IF($J41<>"","EM OBRA","PENDENTE-PROCURAR"))))) -> PENDENTE-PROCURAR | N41: {=IF($A41="","",IFERROR(IF(OR($L41="BAIXADO",$L41="FURTADO"),0,INDEX(Listas!$J$2:$J$40,MATCH($B41,Listas!$I$2:$I$40,0))),""))} -> 200 | P41: {=IF($A41="","",IFERROR(_xlfn.XLOOKUP($A41,'Movimentação'!$B$7:$B$1006,'Movimentação'!$F$7:$F$1006,"",0,-1),""))} | Q41: =IF(COUNTIFS('Manutenção'!$B$7:$B$1006,$A41,'Manutenção'!$H$7:$H$1006,"EM CONSERTO")>0,1,0) -> 0
A42: FRP-14 | B42: ROMPEDOR | C42: Rompedor | D42: THAF | E42: H26F-3 | F42: 202402282 | G42: 903.9 | H42: S | J42: {=IF($A42="","",IFERROR(_xlfn.XLOOKUP($A42,'Movimentação'!$B$7:$B$1006,'Movimentação'!$E$7:$E$1006,"",0,-1),""))} -> MANUTENÇÃO | K42: {=IF($A42="","",IFERROR(_xlfn.XLOOKUP($A42,'Movimentação'!$B$7:$B$1006,'Movimentação'!$G$7:$G$1006,"",0,-1),""))} -> LAÉRCIO | L42: =IF($A42="","",IF($Q42=1,"MANUTENÇÃO",IF($P42="BAIXA","BAIXADO",IF($P42="FURTO","FURTADO",IF($J42<>"","EM OBRA","PENDENTE-PROCURAR"))))) -> MANUTENÇÃO | N42: {=IF($A42="","",IFERROR(IF(OR($L42="BAIXADO",$L42="FURTADO"),0,INDEX(Listas!$J$2:$J$40,MATCH($B42,Listas!$I$2:$I$40,0))),""))} -> 200 | P42: {=IF($A42="","",IFERROR(_xlfn.XLOOKUP($A42,'Movimentação'!$B$7:$B$1006,'Movimentação'!$F$7:$F$1006,"",0,-1),""))} -> ENVIO P/ MANUTENÇÃO | Q42: =IF(COUNTIFS('Manutenção'!$B$7:$B$1006,$A42,'Manutenção'!$H$7:$H$1006,"EM CONSERTO")>0,1,0) -> 1
A43: ESL-01 | B43: ESMERILHADEIRA | C43: Esmerilhadeira | D43: BOSCH | E43: GWS 850 | F43: 332 50 1821 | G43: 284.11 | H43: N | I43: 952463 | J43: {=IF($A43="","",IFERROR(_xlfn.XLOOKUP($A43,'Movimentação'!$B$7:$B$1006,'Movimentação'!$E$7:$E$1006,"",0,-1),""))} -> ASSISTENCIA TECNICA | K43: {=IF($A43="","",IFERROR(_xlfn.XLOOKUP($A43,'Movimentação'!$B$7:$B$1006,'Movimentação'!$G$7:$G$1006,"",0,-1),""))} -> EICES | L43: =IF($A43="","",IF($Q43=1,"MANUTENÇÃO",IF($P43="BAIXA","BAIXADO",IF($P43="FURTO","FURTADO",IF($J43<>"","EM OBRA","PENDENTE-PROCURAR"))))) -> BAIXADO | N43: {=IF($A43="","",IFERROR(IF(OR($L43="BAIXADO",$L43="FURTADO"),0,INDEX(Listas!$J$2:$J$40,MATCH($B43,Listas!$I$2:$I$40,0))),""))} -> 0 | P43: {=IF($A43="","",IFERROR(_xlfn.XLOOKUP($A43,'Movimentação'!$B$7:$B$1006,'Movimentação'!$F$7:$F$1006,"",0,-1),""))} -> BAIXA | Q43: =IF(COUNTIFS('Manutenção'!$B$7:$B$1006,$A43,'Manutenção'!$H$7:$H$1006,"EM CONSERTO")>0,1,0) -> 0
...

Sheet Movimentação
B1: MOVIMENTAÇÃO
B3: Registre 1 linha por evento: mudou de obra, quebrou, sumiu, foi baixada.
A6: Data | B6: Código | C6: Item (auto) | D6: Obra Origem | E6: Obra Destino | F6: Tipo / Motivo | G6: Responsável | H6: Observação
A7: 46235 | B7: PAR-01 | C7: {=IFERROR(INDEX('Patrimônio'!$C$7:$C$1003,MATCH($B7,'Patrimônio'!$A$7:$A$1003,0)),"")} -> Parafusadeira | D7: CARGA INICIAL | E7: PEDRO H | F7: ENTRADA (NOVA) | G7: EICES | H7: sincronizado c/ aferida ago/2026
A8: 46235 | B8: PAR-02 | C8: {=IFERROR(INDEX('Patrimônio'!$C$7:$C$1003,MATCH($B8,'Patrimônio'!$A$7:$A$1003,0)),"")} -> Parafusadeira | D8: CARGA INICIAL | E8: ALPHA ONE | F8: ENTRADA (NOVA) | G8: EICES | H8: sincronizado c/ aferida ago/2026
A9: 46235 | B9: PAR-03 | C9: {=IFERROR(INDEX('Patrimônio'!$C$7:$C$1003,MATCH($B9,'Patrimônio'!$A$7:$A$1003,0)),"")} -> Parafusadeira | E9: ALPHA ONE | F9: FURTO | G9: EICES
A10: 46235 | B10: PAR-04 | C10: {=IFERROR(INDEX('Patrimônio'!$C$7:$C$1003,MATCH($B10,'Patrimônio'!$A$7:$A$1003,0)),"")} -> Parafusadeira | D10: CARGA INICIAL | E10: ALPHA ONE | F10: ENTRADA (NOVA) | G10: EICES | H10: sincronizado c/ aferida ago/2026
A11: 46235 | B11: PAR-05 | C11: {=IFERROR(INDEX('Patrimônio'!$C$7:$C$1003,MATCH($B11,'Patrimônio'!$A$7:$A$1003,0)),"")} -> Parafusadeira | D11: CARGA INICIAL | E11: ALPHA ONE | F11: ENTRADA (NOVA) | G11: EICES | H11: sincronizado c/ aferida ago/2026
A12: 46235 | B12: PAR-5 | C12: {=IFERROR(INDEX('Patrimônio'!$C$7:$C$1003,MATCH($B12,'Patrimônio'!$A$7:$A$1003,0)),"")} -> Parafusadeira | D12: CARGA INICIAL | E12: ALPHA ONE | F12: ENTRADA (NOVA) | G12: EICES | H12: sincronizado c/ aferida ago/2026
A13: 46235 | B13: PAR-06 | C13: {=IFERROR(INDEX('Patrimônio'!$C$7:$C$1003,MATCH($B13,'Patrimônio'!$A$7:$A$1003,0)),"")} -> Parafusadeira | D13: CARGA INICIAL | E13: ANGELICA | F13: ENTRADA (NOVA) | G13: EICES | H13: sincronizado c/ aferida ago/2026
A14: 46235 | B14: PAR-07 | C14: {=IFERROR(INDEX('Patrimônio'!$C$7:$C$1003,MATCH($B14,'Patrimônio'!$A$7:$A$1003,0)),"")} -> Parafusadeira | D14: CARGA INICIAL | E14: TANABI | F14: ENTRADA (NOVA) | G14: EICES | H14: sincronizado c/ aferida ago/2026
A15: 46235 | B15: PAR-09 | C15: {=IFERROR(INDEX('Patrimônio'!$C$7:$C$1003,MATCH($B15,'Patrimônio'!$A$7:$A$1003,0)),"")} -> Parafusadeira | D15: CARGA INICIAL | E15: ESCRITÓRIO | F15: ENTRADA (NOVA) | G15: EICES | H15: sincronizado c/ aferida ago/2026
A16: 46235 | B16: PAR-11 | C16: {=IFERROR(INDEX('Patrimônio'!$C$7:$C$1003,MATCH($B16,'Patrimônio'!$A$7:$A$1003,0)),"")} -> Parafusadeira | D16: CARGA INICIAL | E16: MAURO | F16: ENTRADA (NOVA) | G16: EICES | H16: sincronizado c/ aferida ago/2026
A17: 46235 | B17: PAR-12 | C17: {=IFERROR(INDEX('Patrimônio'!$C$7:$C$1003,MATCH($B17,'Patrimônio'!$A$7:$A$1003,0)),"")} -> Parafusadeira | D17: CARGA INICIAL | E17: ESCRITÓRIO | F17: ENTRADA (NOVA) | G17: EICES | H17: sincronizado c/ aferida ago/2026
A18: 46235 | B18: PAR-14 | C18: {=IFERROR(INDEX('Patrimônio'!$C$7:$C$1003,MATCH($B18,'Patrimônio'!$A$7:$A$1003,0)),"")} -> Parafusadeira | D18: CARGA INICIAL | E18: BIOMA | F18: ENTRADA (NOVA) | G18: EICES | H18: sincronizado c/ aferida ago/2026
A19: 46235 | B19: PAR-15 | C19: {=IFERROR(INDEX('Patrimônio'!$C$7:$C$1003,MATCH($B19,'Patrimônio'!$A$7:$A$1003,0)),"")} -> Parafusadeira | D19: CARGA INICIAL | E19: ARENGA (TRISUL) | F19: ENTRADA (NOVA) | G19: EICES | H19: sincronizado c/ aferida ago/2026
A20: 46235 | B20: PAR-14 | C20: {=IFERROR(INDEX('Patrimônio'!$C$7:$C$1003,MATCH($B20,'Patrimônio'!$A$7:$A$1003,0)),"")} -> Parafusadeira | D20: CARGA INICIAL | E20: ASSISTENCIA TECNICA | F20: ENTRADA (NOVA) | G20: EICES | H20: sincronizado c/ aferida ago/2026
A21: 46235 | B21: PAR-17 | C21: {=IFERROR(INDEX('Patrimônio'!$C$7:$C$1003,MATCH($B21,'Patrimônio'!$A$7:$A$1003,0)),"")} -> Parafusadeira | D21: CARGA INICIAL | E21: PJM | F21: ENTRADA (NOVA) | G21: EICES | H21: sincronizado c/ aferida ago/2026
... A26: 46235 | B26: FRP-01 | C26: {=IFERROR(INDEX('Patrimônio'!$C$7:$C$1003,MATCH($B26,'Patrimônio'!$A$7:$A$1003,0)),"")} -> Rompedor | D26: CARGA INICIAL | E26: ORIÇANGA | F26: ENTRADA (NOVA) | G26: EICES | H26: sincronizado c/ aferida ago/2026
A27: 46235 | B27: FRP-02 | C27: {=IFERROR(INDEX('Patrimônio'!$C$7:$C$1003,MATCH($B27,'Patrimônio'!$A$7:$A$1003,0)),"")} -> Rompedor | F27: BAIXA | G27: EICES | H27: baixa (perda total)
A28: 46235 | B28: FRP-03 | C28: {=IFERROR(INDEX('Patrimônio'!$C$7:$C$1003,MATCH($B28,'Patrimônio'!$A$7:$A$1003,0)),"")} -> Rompedor | D28: CARGA INICIAL | E28: DIEGO | F28: ENTRADA (NOVA) | G28: EICES | H28: sincronizado c/ aferida ago/2026
A29: 46235 | B29: FRP-05 | C29: {=IFERROR(INDEX('Patrimônio'!$C$7:$C$1003,MATCH($B29,'Patrimônio'!$A$7:$A$1003,0)),"")} -> Rompedor | D29: CARGA INICIAL | E29: TANABI | F29: ENTRADA (NOVA) | G29: EICES | H29: sincronizado c/ aferida ago/2026
A30: 46235 | B30: FRP-06 | C30: {=IFERROR(INDEX('Patrimônio'!$C$7:$C$1003,MATCH($B30,'Patrimônio'!$A$7:$A$1003,0)),"")} -> Rompedor | D30: CARGA INICIAL | E30: ORIÇANGA | F30: ENTRADA (NOVA) | G30: EICES | H30: sincronizado c/ aferida ago/2026
A31: 46235 | B31: FRP-07 | C31: {=IFERROR(INDEX('Patrimônio'!$C$7:$C$1003,MATCH($B31,'Patrimônio'!$A$7:$A$1003,0)),"")} -> Rompedor | D31: CARGA INICIAL | E31: ALPHA ONE | F31: ENTRADA (NOVA) | G31: EICES | H31: sincronizado c/ aferida ago/2026
A32: 46235 | B32: FRP-08 | C32: {=IFERROR(INDEX('Patrimônio'!$C$7:$C$1003,MATCH($B32,'Patrimônio'!$A$7:$A$1003,0)),"")} -> Rompedor | D32: CARGA INICIAL | E32: MAURO | F32: ENTRADA (NOVA) | G32: EICES | H32: sincronizado c/ aferida ago/2026
A33: 46235 | B33: FRP-09 | C33: {=IFERROR(INDEX('Patrimônio'!$C$7:$C$1003,MATCH($B33,'Patrimônio'!$A$7:$A$1003,0)),"")} -> Rompedor | D33: CARGA INICIAL | E33: ALTIER | F33: ENTRADA (NOVA) | G33: EICES | H33: sincronizado c/ aferida ago/2026
A34: 46235 | B34: FRP-10 | C34: {=IFERROR(INDEX('Patrimônio'!$C$7:$C$1003,MATCH($B34,'Patrimônio'!$A$7:$A$1003,0)),"")} -> Rompedor | D34: CARGA INICIAL | E34: JOA | F34: ENTRADA (NOVA) | G34: EICES | H34: sincronizado c/ aferida ago/2026
A35: 46235 | B35: FRP-11 | C35: {=IFERROR(INDEX('Patrimônio'!$C$7:$C$1003,MATCH($B35,'Patrimônio'!$A$7:$A$1003,0)),"")} -> Rompedor | D35: CARGA INICIAL | E35: PJM | F35: ENTRADA (NOVA) | G35: EICES | H35: sincronizado c/ aferida ago/2026
A36: 46235 | B36: FRP-12 | C36: {=IFERROR(INDEX('Patrimônio'!$C$7:$C$1003,MATCH($B36,'Patrimônio'!$A$7:$A$1003,0)),"")} -> Rompedor | D36: CARGA INICIAL | E36: SAMPA CONSOLAÇÃO | F36: ENTRADA (NOVA) | G36: EICES | H36: sincronizado c/ aferida ago/2026
A37: 46235 | B37: FRP-14 | C37: {=IFERROR(INDEX('Patrimônio'!$C$7:$C$1003,MATCH($B37,'Patrimônio'!$A$7:$A$1003,0)),"")} -> Rompedor | D37: CARGA INICIAL | E37: MAURO | F37: ENTRADA (NOVA) | G37: EICES | H37: sincronizado c/ aferida ago/2026
A38: 46235 | B38: ESL-01 | C38: {=IFERROR(INDEX('Patrimônio'!$C$7:$C$1003,MATCH($B38,'Patrimônio'!$A$7:$A$1003,0)),"")} -> Esmerilhadeira | D38: CARGA INICIAL | E38: PEDRO H | F38: ENTRADA (NOVA) | G38: EICES | H38: sincronizado c/ aferida ago/2026
A39: 46235 | B39: ESL-02 | C39: {=IFERROR(INDEX('Patrimônio'!$C$7:$C$1003,MATCH($B39,'Patrimônio'!$A$7:$A$1003,0)),"")} -> Esmerilhadeira | D39: CARGA INICIAL | E39: MAURO | F39: ENTRADA (NOVA) | G39: EICES | H39: sincronizado c/ aferida ago/2026
... A43: 46235 | B43: MSE-01 | C43: {=IFERROR(INDEX('Patrimônio'!$C$7:$C$1003,MATCH($B43,'Patrimônio'!$A$7:$A$1003,0)),"")} -> Serra Mármore | D43: CARGA INICIAL | E43: PEDRO H | F43: ENTRADA (NOVA) | G43: EICES | H43: sincronizado c/ aferida ago/2026
A44: 46235 | B44: MSE-02 | C44: {=IFERROR(INDEX('Patrimônio'!$C$7:$C$1003,MATCH($B44,'Patrimônio'!$A$7:$A$1003,0)),"")} -> Serra Mármore | F44: BAIXA | G44: EICES | H44: baixa (perda total)
A45: 46235 | B45: MSE-03 | C45: {=IFERROR(INDEX('Patrimônio'!$C$7:$C$1003,MATCH($B45,'Patrimônio'!$A$7:$A$1003,0)),"")} -> Serra Mármore | D45: CARGA INICIAL | E45: ALPHA ONE | F45: ENTRADA (NOVA) | G45: EICES | H45: sincronizado c/ aferida ago/2026
A46: 46235 | B46: MSE-04 | C46: {=IFERROR(INDEX('Patrimônio'!$C$7:$C$1003,MATCH($B46,'Patrimônio'!$A$7:$A$1003,0)),"")} -> Serra Mármore | D46: CARGA INICIAL | E46: ALTIER | F46: ENTRADA (NOVA) | G46: EICES | H46: sincronizado c/ aferida ago/2026
A47: 46235 | B47: MSE-05 | C47: {=IFERROR(INDEX('Patrimônio'!$C$7:$C$1003,MATCH($B47,'Patrimônio'!$A$7:$A$1003,0)),"")} -> Serra Mármore | D47: CARGA INICIAL | E47: ORIÇANGA | F47: ENTRADA (NOVA) | G47: EICES | H47: sincronizado c/ aferida ago/2026
A48: 46235 | B48: MSE-06 | C48: {=IFERROR(INDEX('Patrimônio'!$C$7:$C$1003,MATCH($B48,'Patrimônio'!$A$7:$A$1003,0)),"")} -> Serra Mármore | D48: CARGA INICIAL | E48: SAMPA CONSOLAÇÃO | F48: ENTRADA (NOVA) | G48: EICES | H48: sincronizado c/ aferida ago/2026
A49: 46235 | B49: MSE-07 | C49: {=IFERROR(INDEX('Patrimônio'!$C$7:$C$1003,MATCH($B49,'Patrimônio'!$A$7:$A$1003,0)),"")} -> Serra Mármore | D49: CARGA INICIAL | E49: MAURO | F49: ENTRADA (NOVA) | G49: EICES | H49: sincronizado c/ aferida ago/2026
A50: 46235 | B50: CMA-01 | C50: {=IFERROR(INDEX('Patrimônio'!$C$7:$C$1003,MATCH($B50,'Patrimônio'!$A$7:$A$1003,0)),"")} -> Martelete 5Kg | D50: CARGA INICIAL | E50: MAURO | F50: ENTRADA (NOVA) | G50: EICES | H50: sincronizado c/ aferida ago/2026
...

Sheet Manutenção
B1: MANUTENÇÃO — FICHA DE CONSERTOS
B3: Cada conserto = 1 linha. Alimenta o giro de estoque e o custo de manutenção.
A6: Data Entrada | B6: Código | C6: Item (auto) | D6: Categoria (auto) | E6: Obra onde Quebrou | F6: Custo (R$) | G6: Data Retorno | H6: Status | I6: Obra Retorno | J6: Dias Parado (auto) | K6: Observação
A7: 46235 | B7: PAR-18 | C7: {=IFERROR(INDEX('Patrimônio'!$C$7:$C$1003,MATCH($B7,'Patrimônio'!$A$7:$A$1003,0)),"")} -> Parafusadeira | D7: {=IFERROR(INDEX('Patrimônio'!$B$7:$B$1003,MATCH($B7,'Patrimônio'!$A$7:$A$1003,0)),"")} -> PARAFUSADEIRA | E7: ANGELICA | G7: 46246 | H7: VOLTOU | I7: ANGELICA | J7: =IF(AND($A7<>"",$G7<>""),$G7-$A7,"") -> 11 | K7: auditoria ago/2026
A8: 46235 | B8: FRP-06 | C8: {=IFERROR(INDEX('Patrimônio'!$C$7:$C$1003,MATCH($B8,'Patrimônio'!$A$7:$A$1003,0)),"")} -> Rompedor | D8: {=IFERROR(INDEX('Patrimônio'!$B$7:$B$1003,MATCH($B8,'Patrimônio'!$A$7:$A$1003,0)),"")} -> ROMPEDOR | E8: ORIÇANGA | G8: 46248 | H8: VOLTOU | I8: SAMPA CONSOLAÇÃO | J8: =IF(AND($A8<>"",$G8<>""),$G8-$A8,"") -> 13 | K8: auditoria ago/2026
A9: 46235 | B9: PEZ-02 | C9: {=IFERROR(INDEX('Patrimônio'!$C$7:$C$1003,MATCH($B9,'Patrimônio'!$A$7:$A$1003,0)),"")} -> Perfuratriz | D9: {=IFERROR(INDEX('Patrimônio'!$B$7:$B$1003,MATCH($B9,'Patrimônio'!$A$7:$A$1003,0)),"")} -> PERFURATRIZ | E9: ORIÇANGA | G9: 46244 | H9: VOLTOU | I9: ORIÇANGA | J9: =IF(AND($A9<>"",$G9<>""),$G9-$A9,"") -> 9 | K9: auditoria ago/2026
A10: 46235 | B10: PEZ-12 | C10: {=IFERROR(INDEX('Patrimônio'!$C$7:$C$1003,MATCH($B10,'Patrimônio'!$A$7:$A$1003,0)),"")} -> Perfuratriz | D10: {=IFERROR(INDEX('Patrimônio'!$B$7:$B$1003,MATCH($B10,'Patrimônio'!$A$7:$A$1003,0)),"")} -> PERFURATRIZ | E10: JOA | H10: VOLTOU | J10: =IF(AND($A10<>"",$G10<>""),$G10-$A10,"") | K10: auditoria ago/2026
A11: 46235 | B11: TER-04 | C11: {=IFERROR(INDEX('Patrimônio'!$C$7:$C$1003,MATCH($B11,'Patrimônio'!$A$7:$A$1003,0)),"")} -> Termofusor | D11: {=IFERROR(INDEX('Patrimônio'!$B$7:$B$1003,MATCH($B11,'Patrimônio'!$A$7:$A$1003,0)),"")} -> TERMOFUSOR | E11: SAMPA CONSOLAÇÃO | G11: 46235 | H11: VOLTOU | I11: SAMPA CONSOLAÇÃO | J11: =IF(AND($A11<>"",$G11<>""),$G11-$A11,"") -> 0 | K11: auditoria ago/2026
A12: 46235 | B12: TER-06 | C12: {=IFERROR(INDEX('Patrimônio'!$C$7:$C$1003,MATCH($B12,'Patrimônio'!$A$7:$A$1003,0)),"")} -> Termofusor | D12: {=IFERROR(INDEX('Patrimônio'!$B$7:$B$1003,MATCH($B12,'Patrimônio'!$A$7:$A$1003,0)),"")} -> TERMOFUSOR | E12: SAMPA CONSOLAÇÃO | G12: 46235 | H12: VOLTOU | I12: SAMPA CONSOLAÇÃO | J12: =IF(AND($A12<>"",$G12<>""),$G12-$A12,"") -> 0 | K12: auditoria ago/2026
A13: 46235 | B13: PFP-12 | C13: {=IFERROR(INDEX('Patrimônio'!$C$7:$C$1003,MATCH($B13,'Patrimônio'!$A$7:$A$1003,0)),"")} -> Pistola Finca Pino | D13: {=IFERROR(INDEX('Patrimônio'!$B$7:$B$1003,MATCH($B13,'Patrimônio'!$A$7:$A$1003,0)),"")} -> PISTOLA FINCA PINO | E13: ARENGA (TRISUL) | H13: BAIXA | J13: =IF(AND($A13<>"",$G13<>""),$G13-$A13,"") | K13: auditoria ago/2026
A14: 46235 | B14: PPE-02 | C14: {=IFERROR(INDEX('Patrimônio'!$C$7:$C$1003,MATCH($B14,'Patrimônio'!$A$7:$A$1003,0)),"")} -> Prensa Pex | D14: {=IFERROR(INDEX('Patrimônio'!$B$7:$B$1003,MATCH($B14,'Patrimônio'!$A$7:$A$1003,0)),"")} -> PRENSA PEX | E14: SAMPA CONSOLAÇÃO | H14: BAIXA | J14: =IF(AND($A14<>"",$G14<>""),$G14-$A14,"") | K14: SEM CONSERTO
A15: 46253 | B15: PEZ-10 | C15: {=IFERROR(INDEX('Patrimônio'!$C$7:$C$1003,MATCH($B15,'Patrimônio'!$A$7:$A$1003,0)),"")} -> Perfuratriz | D15: {=IFERROR(INDEX('Patrimônio'!$B$7:$B$1003,MATCH($B15,'Patrimônio'!$A$7:$A$1003,0)),"")} -> PERFURATRIZ | E15: JOA | G15: 46258 | H15: VOLTOU | I15: JOA | J15: =IF(AND($A15<>"",$G15<>""),$G15-$A15,"") -> 5
A16: 46258 | B16: FRP-14 | C16: {=IFERROR(INDEX('Patrimônio'!$C$7:$C$1003,MATCH($B16,'Patrimônio'!$A$7:$A$1003,0)),"")} -> Rompedor | D16: {=IFERROR(INDEX('Patrimônio'!$B$7:$B$1003,MATCH($B16,'Patrimônio'!$A$7:$A$1003,0)),"")} -> ROMPEDOR | E16: MAURO | H16: EM CONSERTO | J16: =IF(AND($A16<>"",$G16<>""),$G16-$A16,"")
A17: 46258 | B17: PAR-01 | C17: {=IFERROR(INDEX('Patrimônio'!$C$7:$C$1003,MATCH($B17,'Patrimônio'!$A$7:$A$1003,0)),"")} -> Parafusadeira | D17: {=IFERROR(INDEX('Patrimônio'!$B$7:$B$1003,MATCH($B17,'Patrimônio'!$A$7:$A$1003,0)),"")} -> PARAFUSADEIRA | G17: 46258 | H17: VOLTOU | I17: ALTIER | J17: =IF(AND($A17<>"",$G17<>""),$G17-$A17,"") -> 0
A18: 46260 | B18: PEZ-03 | C18: {=IFERROR(INDEX('Patrimônio'!$C$7:$C$1003,MATCH($B18,'Patrimônio'!$A$7:$A$1003,0)),"")} -> Perfuratriz | D18: {=IFERROR(INDEX('Patrimônio'!$B$7:$B$1003,MATCH($B18,'Patrimônio'!$A$7:$A$1003,0)),"")} -> PERFURATRIZ | E18: JOA | G18: 46268 | H18: VOLTOU | I18: JERONIMO | J18: =IF(AND($A18<>"",$G18<>""),$G18-$A18,"") -> 8
A19: 46261 | B19: FRP-09 | C19: {=IFERROR(INDEX('Patrimônio'!$C$7:$C$1003,MATCH($B19,'Patrimônio'!$A$7:$A$1003,0)),"")} -> Rompedor | D19: {=IFERROR(INDEX('Patrimônio'!$B$7:$B$1003,MATCH($B19,'Patrimônio'!$A$7:$A$1003,0)),"")} -> ROMPEDOR | E19: ALTIER | H19: BAIXA | J19: =IF(AND($A19<>"",$G19<>""),$G19-$A19,"")
A20: 46274 | B20: PEZ-10 | C20: {=IFERROR(INDEX('Patrimônio'!$C$7:$C$1003,MATCH($B20,'Patrimônio'!$A$7:$A$1003,0)),"")} -> Perfuratriz | D20: {=IFERROR(INDEX('Patrimônio'!$B$7:$B$1003,MATCH($B20,'Patrimônio'!$A$7:$A$1003,0)),"")} -> PERFURATRIZ | E20: JOA | G20: 46275 | H20: VOLTOU | I20: ANGELICA | J20: =IF(AND($A20<>"",$G20<>""),$G20-$A20,"") -> 1
A21: 46235 | B21: CMA-05 | C21: {=IFERROR(INDEX('Patrimônio'!$C$7:$C$1003,MATCH($B21,'Patrimônio'!$A$7:$A$1003,0)),"")} -> Martelete 5Kg | D21: {=IFERROR(INDEX('Patrimônio'!$B$7:$B$1003,MATCH($B21,'Patrimônio'!$A$7:$A$1003,0)),"")} -> MARTELETE 5KG | E21: CARGA INICIAL | H21: VOLTOU | I21: ESCRITORIO | J21: =IF(AND($A21<>"",$G21<>""),$G21-$A21,"")
A22: 46281 | B22: PEZ-12 | C22: {=IFERROR(INDEX('Patrimônio'!$C$7:$C$1003,MATCH($B22,'Patrimônio'!$A$7:$A$1003,0)),"")} -> Perfuratriz | D22: {=IFERROR(INDEX('Patrimônio'!$B$7:$B$1003,MATCH($B22,'Patrimônio'!$A$7:$A$1003,0)),"")} -> PERFURATRIZ | E22: SAMPA CONSOLAÇÃO | H22: EM CONSERTO | J22: =IF(AND($A22<>"",$G22<>""),$G22-$A22,"")
C23: {=IFERROR(INDEX('Patrimônio'!$C$7:$C$1003,MATCH($B23,'Patrimônio'!$A$7:$A$1003,0)),"")} | D23: {=IFERROR(INDEX('Patrimônio'!$B$7:$B$1003,MATCH($B23,'Patrimônio'!$A$7:$A$1003,0)),"")} | J23: =IF(AND($A23<>"",$G23<>""),$G23-$A23,"")
C24: {=IFERROR(INDEX('Patrimônio'!$C$7:$C$1003,MATCH($B24,'Patrimônio'!$A$7:$A$1003,0)),"")} | D24: {=IFERROR(INDEX('Patrimônio'!$B$7:$B$1003,MATCH($B24,'Patrimônio'!$A$7:$A$1003,0)),"")} | J24: =IF(AND($A24<>"",$G24<>""),$G24-$A24,"")
C25: {=IFERROR(INDEX('Patrimônio'!$C$7:$C$1003,MATCH($B25,'Patrimônio'!$A$7:$A$1003,0)),"")} | D25: {=IFERROR(INDEX('Patrimônio'!$B$7:$B$1003,MATCH($B25,'Patrimônio'!$A$7:$A$1003,0)),"")} | J25: =IF(AND($A25<>"",$G25<>""),$G25-$A25,"")
C26: {=IFERROR(INDEX('Patrimônio'!$C$7:$C$1003,MATCH($B26,'Patrimônio'!$A$7:$A$1003,0)),"")} | D26: {=IFERROR(INDEX('Patrimônio'!$B$7:$B$1003,MATCH($B26,'Patrimônio'!$A$7:$A$1003,0)),"")} | J26: =IF(AND($A26<>"",$G26<>""),$G26-$A26,"")
C27: {=IFERROR(INDEX('Patrimônio'!$C$7:$C$1003,MATCH($B27,'Patrimônio'!$A$7:$A$1003,0)),"")} | D27: {=IFERROR(INDEX('Patrimônio'!$B$7:$B$1003,MATCH($B27,'Patrimônio'!$A$7:$A$1003,0)),"")} | J27: =IF(AND($A27<>"",$G27<>""),$G27-$A27,"")
C28: {=IFERROR(INDEX('Patrimônio'!$C$7:$C$1003,MATCH($B28,'Patrimônio'!$A$7:$A$1003,0)),"")} | D28: {=IFERROR(INDEX('Patrimônio'!$B$7:$B$1003,MATCH($B28,'Patrimônio'!$A$7:$A$1003,0)),"")} | J28: =IF(AND($A28<>"",$G28<>""),$G28-$A28,"")
C29: {=IFERROR(INDEX('Patrimônio'!$C$7:$C$1003,MATCH($B29,'Patrimônio'!$A$7:$A$1003,0)),"")} | D29: {=IFERROR(INDEX('Patrimônio'!$B$7:$B$1003,MATCH($B29,'Patrimônio'!$A$7:$A$1003,0)),"")} | J29: =IF(AND($A29<>"",$G29<>""),$G29-$A29,"")
C30: {=IFERROR(INDEX('Patrimônio'!$C$7:$C$1003,MATCH($B30,'Patrimônio'!$A$7:$A$1003,0)),"")} | D30: {=IFERROR(INDEX('Patrimônio'!$B$7:$B$1003,MATCH($B30,'Patrimônio'!$A$7:$A$1003,0)),"")} | J30: =IF(AND($A30<>"",$G30<>""),$G30-$A30,"")
C31: {=IFERROR(INDEX('Patrimônio'!$C$7:$C$1003,MATCH($B31,'Patrimônio'!$A$7:$A$1003,0)),"")} | D31: {=IFERROR(INDEX('Patrimônio'!$B$7:$B$1003,MATCH($B31,'Patrimônio'!$A$7:$A$1003,0)),"")} | J31: =IF(AND($A31<>"",$G31<>""),$G31-$A31,"")
C32: {=IFERROR(INDEX('Patrimônio'!$C$7:$C$1003,MATCH($B32,'Patrimônio'!$A$7:$A$1003,0)),"")} | D32: {=IFERROR(INDEX('Patrimônio'!$B$7:$B$1003,MATCH($B32,'Patrimônio'!$A$7:$A$1003,0)),"")} | J32: =IF(AND($A32<>"",$G32<>""),$G32-$A32,"")
C33: {=IFERROR(INDEX('Patrimônio'!$C$7:$C$1003,MATCH($B33,'Patrimônio'!$A$7:$A$1003,0)),"")} | D33: {=IFERROR(INDEX('Patrimônio'!$B$7:$B$1003,MATCH($B33,'Patrimônio'!$A$7:$A$1003,0)),"")} | J33: =IF(AND($A33<>"",$G33<>""),$G33-$A33,"")
C34: {=IFERROR(INDEX('Patrimônio'!$C$7:$C$1003,MATCH($B34,'Patrimônio'!$A$7:$A$1003,0)),"")} | D34: {=IFERROR(INDEX('Patrimônio'!$B$7:$B$1003,MATCH($B34,'Patrimônio'!$A$7:$A$1003,0)),"")} | J34: =IF(AND($A34<>"",$G34<>""),$G34-$A34,"")
... C1006: {=IFERROR(INDEX('Patrimônio'!$C$7:$C$1003,MATCH($B1006,'Patrimônio'!$A$7:$A$1003,0)),"")} | D1006: {=IFERROR(INDEX('Patrimônio'!$B$7:$B$1003,MATCH($B1006,'Patrimônio'!$A$7:$A$1003,0)),"")} | J1006: =IF(AND($A1006<>"",$G1006<>""),$G1006-$A1006,"")

Sheet Rádio
B1: RÁDIO — CONTROLE POR OBRA
B3: Rádio é sempre locado (nunca patrimônio). Preencha a Data Devolução ao encerrar a obra — o custo sai sozinho.
A6: 1. SITUAÇÃO ATUAL POR OBRA
A7: Obra | B7: Locadora | C7: Qtd Atual | D7: Custo Mensal Unit. (R$) | E7: Custo Mensal Total (R$) | F7: Data Início | G7: Data Devolução | H7: Status | I7: Observação
A8: TANABI | B8: STOCK TOTAL | C8: 4 | D8: 65 | E8: =IF($C8="","",IF($G8<>"",0,$C8*$D8)) -> 260 | F8: 46143 | H8: =IF($A8="","",IF($G8<>"","ENCERRADO","ATIVO")) -> ATIVO | I8: carga inicial ago/2026
A9: ANGELICA | B9: OLUAP | C9: 5 | D9: 71.88 | E9: =IF($C9="","",IF($G9<>"",0,$C9*$D9)) -> 359.4 | H9: =IF($A9="","",IF($G9<>"","ENCERRADO","ATIVO")) -> ATIVO | I9: carga inicial ago/2026
A10: ALTIER | B10: OLUAP | C10: 4 | D10: 71.88 | E10: =IF($C10="","",IF($G10<>"",0,$C10*$D10)) -> 287.52 | H10: =IF($A10="","",IF($G10<>"","ENCERRADO","ATIVO")) -> ATIVO | I10: carga inicial ago/2026
A11: MAURO | B11: RADIO WAY | C11: 6 | D11: 78 | E11: =IF($C11="","",IF($G11<>"",0,$C11*$D11)) -> 468 | H11: =IF($A11="","",IF($G11<>"","ENCERRADO","ATIVO")) -> ATIVO | I11: carga inicial ago/2026
A12: PJM | B12: OLUAP | C12: 6 | D12: 71.88 | E12: =IF($C12="","",IF($G12<>"",0,$C12*$D12)) -> 431.28 | F12: 46121 | H12: =IF($A12="","",IF($G12<>"","ENCERRADO","ATIVO")) -> ATIVO | I12: entrada de 3 uni em 21/08/2026
A13: BALTAZAR | B13: HALCEPE | C13: 3 | D13: 49 | E13: =IF($C13="","",IF($G13<>"",0,$C13*$D13)) -> 147 | F13: 46136 | H13: =IF($A13="","",IF($G13<>"","ENCERRADO","ATIVO")) -> ATIVO | I13: carga inicial ago/2026
A14: SAMPA CONSOLAÇÃO | B14: OLUAP | C14: 6 | D14: 71.88 | E14: =IF($C14="","",IF($G14<>"",0,$C14*$D14)) -> 431.28 | H14: =IF($A14="","",IF($G14<>"","ENCERRADO","ATIVO")) -> ATIVO | I14: entrada de 3 uni em 21/08/2026
A15: ORIÇANGA | B15: RADIO WAY | C15: 4 | D15: 78 | E15: =IF($C15="","",IF($G15<>"",0,$C15*$D15)) -> 312 | H15: =IF($A15="","",IF($G15<>"","ENCERRADO","ATIVO")) -> ATIVO | I15: carga inicial ago/2026
A16: VIRGILIO | B16: STOCK TOTAL | C16: 0 | D16: 65 | E16: =IF($C16="","",IF($G16<>"",0,$C16*$D16)) -> 0 | F16: 46157 | H16: =IF($A16="","",IF($G16<>"","ENCERRADO","ATIVO")) -> ATIVO | I16: carga inicial ago/2026
A17: CUNHA GAGO | B17: HALCEPE | C17: 6 | D17: 49 | E17: =IF($C17="","",IF($G17<>"",0,$C17*$D17)) -> 294 | F17: 46261 | H17: =IF($A17="","",IF($G17<>"","ENCERRADO","ATIVO")) -> ATIVO
A18: ARENGA (TRISUL) | B18: OLUAP | C18: 3 | D18: 71.88 | E18: =IF($C18="","",IF($G18<>"",0,$C18*$D18)) -> 215.64 | H18: =IF($A18="","",IF($G18<>"","ENCERRADO","ATIVO")) -> ATIVO
A19: JERONIMO | B19: OLUAP | C19: 5 | D19: 71.88 | E19: =IF($C19="","",IF($G19<>"",0,$C19*$D19)) -> 359.4 | F19: 46280 | H19: =IF($A19="","",IF($G19<>"","ENCERRADO","ATIVO")) -> ATIVO
A20: JOA | B20: OLUAP | C20: 4 | D20: 71.88 | E20: =IF($C20="","",IF($G20<>"",0,$C20*$D20)) -> 287.52 | F20: 46281 | H20: =IF($A20="","",IF($G20<>"","ENCERRADO","ATIVO")) -> ATIVO
E21: =IF($C21="","",IF($G21<>"",0,$C21*$D21)) | H21: =IF($A21="","",IF($G21<>"","ENCERRADO","ATIVO"))
E22: =IF($C22="","",IF($G22<>"",0,$C22*$D22)) | H22: =IF($A22="","",IF($G22<>"","ENCERRADO","ATIVO"))
E23: =IF($C23="","",IF($G23<>"",0,$C23*$D23)) | H23: =IF($A23="","",IF($G23<>"","ENCERRADO","ATIVO"))
E24: =IF($C24="","",IF($G24<>"",0,$C24*$D24)) | H24: =IF($A24="","",IF($G24<>"","ENCERRADO","ATIVO"))
E25: =IF($C25="","",IF($G25<>"",0,$C25*$D25)) | H25: =IF($A25="","",IF($G25<>"","ENCERRADO","ATIVO"))
E26: =IF($C26="","",IF($G26<>"",0,$C26*$D26)) | H26: =IF($A26="","",IF($G26<>"","ENCERRADO","ATIVO"))
E27: =IF($C27="","",IF($G27<>"",0,$C27*$D27)) | H27: =IF($A27="","",IF($G27<>"","ENCERRADO","ATIVO"))
E28: =IF($C28="","",IF($G28<>"",0,$C28*$D28)) | H28: =IF($A28="","",IF($G28<>"","ENCERRADO","ATIVO"))
E29: =IF($C29="","",IF($G29<>"",0,$C29*$D29)) | H29: =IF($A29="","",IF($G29<>"","ENCERRADO","ATIVO"))
E30: =IF($C30="","",IF($G30<>"",0,$C30*$D30)) | H30: =IF($A30="","",IF($G30<>"","ENCERRADO","ATIVO"))
E31: =IF($C31="","",IF($G31<>"",0,$C31*$D31)) | H31: =IF($A31="","",IF($G31<>"","ENCERRADO","ATIVO"))
E32: =IF($C32="","",IF($G32<>"",0,$C32*$D32)) | H32: =IF($A32="","",IF($G32<>"","ENCERRADO","ATIVO"))
... E37: =IF($C37="","",IF($G37<>"",0,$C37*$D37)) | H37: =IF($A37="","",IF($G37<>"","ENCERRADO","ATIVO"))
D38: TOTAL MENSAL RÁDIO: | E38: =SUM($E$8:$E$37) -> 3853.04
A40: 2. HISTÓRICO DE EVENTOS (entrega / quebra / sumiço / reposição)
A41: Data | B41: Obra | C41: Locadora | D41: Evento | E41: Qtd | F41: Custo do Item (R$) | G41: Recuperado de | H41: Observação
A93: RESUMO DE PERDAS DE RÁDIO
A94: Total perdido/quebrado (R$): | C94: =SUMIFS($F$42:$F$91,$D$42:$D$91,"SUMIÇO")+SUMIFS($F$42:$F$91,$D$42:$D$91,"QUEBRA") -> 0
A95: Recuperado (empreiteiro+equipe): | C95: =SUMIFS($F$42:$F$91,$G$42:$G$91,"EMPREITEIRO")+SUMIFS($F$42:$F$91,$G$42:$G$91,"EQUIPE DA OBRA") -> 0
A96: Prejuízo EICES (não recuperado): | C96: =SUMIFS($F$42:$F$91,$G$42:$G$91,"NINGUÉM (PREJUÍZO EICES)") -> 0

Sheet Locado
B1: LOCADO — FERRAMENTAS ALUGADAS DE TERCEIROS
B3: Controle do custo mensal. Preencha a Data Devolução ao encerrar — o custo sai sozinho.
